2025-08-23 16:14:27,102 - __main__ - INFO - Запуск Telegram-бота
2025-08-23 16:14:51,293 - __main__ - ERROR - Недоступный URL: https://www.ozon.ru/product/dzhinsy-befree-883110146/, код: 403
2025-08-23 16:15:54,013 - __main__ - WARNING - Невалидный URL: /start от пользователя 515084006
2025-08-23 16:15:59,754 - __main__ - ERROR - Недоступный URL: https://www.ozon.ru/product/dzhinsy-befree-883110146/, код: 403
2025-08-23 16:29:45,029 - src.infrastructure.core.session_engine - INFO - WebDriver успешно инициализирован.
2025-08-23 16:29:55,244 - src.infrastructure.core.session_engine - INFO - Успешно загружена страница: https://www.ozon.ru/product/dzhinsy-befree-883110146/
2025-08-23 16:29:55,244 - __main__ - INFO - Загружена страница: https://www.ozon.ru/product/dzhinsy-befree-883110146/
2025-08-23 16:29:55,309 - __main__ - INFO - Найдено название товара: Джинсы Befree
2025-08-23 16:29:55,339 - __main__ - INFO - Найден артикул: 883110146
2025-08-23 16:29:55,369 - __main__ - INFO - Текст рейтинга: 4.9 • 212 отзывов
2025-08-23 16:29:55,371 - __main__ - INFO - Найден рейтинг: 4.9
2025-08-23 16:29:55,402 - __main__ - INFO - Найдена цена с картой: 1819
2025-08-23 16:29:55,431 - __main__ - INFO - Найдена цена без карты: 1954
2025-08-23 16:29:55,457 - __main__ - INFO - Найдена базовая цена: 5299
2025-08-23 16:29:55,492 - __main__ - INFO - Найден URL изображения: https://ir.ozone.ru/s3/multimedia-1-b/wc1000/7208661467.jpg
2025-08-23 16:29:55,573 - __main__ - INFO - Найдены категории: ['Одежда', 'Мужчинам', 'Джинсы', 'Befree']
2025-08-23 16:29:56,801 - src.infrastructure.core.session_engine - INFO - WebDriver успешно закрыт.
2025-08-23 16:35:23,924 - src.infrastructure.core.session_engine - INFO - WebDriver успешно инициализирован.
2025-08-23 16:35:34,133 - src.infrastructure.core.session_engine - INFO - Успешно загружена страница: https://www.ozon.ru/product/dzhinsy-befree-883110146/
2025-08-23 16:35:34,134 - __main__ - INFO - Загружена страница: https://www.ozon.ru/product/dzhinsy-befree-883110146/
2025-08-23 16:35:34,189 - __main__ - INFO - Найдено название товара: Джинсы Befree
2025-08-23 16:35:34,207 - __main__ - INFO - Найден артикул: 883110146
2025-08-23 16:35:34,225 - __main__ - INFO - Текст рейтинга: 4.9 • 212 отзывов
2025-08-23 16:35:34,226 - __main__ - INFO - Найден рейтинг: 4.9
2025-08-23 16:35:34,246 - __main__ - INFO - Найдена цена с картой: 1819
2025-08-23 16:35:34,266 - __main__ - INFO - Найдена цена без карты: 1954
2025-08-23 16:35:34,282 - __main__ - INFO - Найдена базовая цена: 5299
2025-08-23 16:35:34,307 - __main__ - INFO - Найден URL изображения: https://ir.ozone.ru/s3/multimedia-1-b/wc1000/7208661467.jpg
2025-08-23 16:35:34,406 - __main__ - INFO - Найдены категории: ['Одежда', 'Мужчинам', 'Джинсы', 'Befree']
2025-08-23 16:35:35,672 - src.infrastructure.core.session_engine - INFO - WebDriver успешно закрыт.
2025-08-23 16:36:12,770 - src.infrastructure.core.session_engine - INFO - WebDriver успешно инициализирован.
2025-08-23 16:36:22,947 - src.infrastructure.core.session_engine - INFO - Успешно загружена страница: https://www.ozon.ru/product/dzhinsy-befree-883110146/
2025-08-23 16:36:22,948 - __main__ - INFO - Загружена страница: https://www.ozon.ru/product/dzhinsy-befree-883110146/
2025-08-23 16:36:22,988 - __main__ - INFO - Найдено название товара: Джинсы Befree
2025-08-23 16:36:23,001 - __main__ - INFO - Найден артикул: 883110146
2025-08-23 16:36:23,017 - __main__ - INFO - Текст рейтинга: 4.9 • 212 отзывов
2025-08-23 16:36:23,017 - __main__ - INFO - Найден рейтинг: 4.9
2025-08-23 16:36:23,034 - __main__ - INFO - Найдена цена с картой: 1819
2025-08-23 16:36:23,050 - __main__ - INFO - Найдена цена без карты: 1954
2025-08-23 16:36:23,070 - __main__ - INFO - Найдена базовая цена: 5299
2025-08-23 16:36:23,095 - __main__ - INFO - Найден URL изображения: https://ir.ozone.ru/s3/multimedia-1-b/wc1000/7208661467.jpg
2025-08-23 16:36:23,157 - __main__ - INFO - Найдены категории: ['Одежда', 'Мужчинам', 'Джинсы', 'Befree']
2025-08-23 16:36:24,433 - src.infrastructure.core.session_engine - INFO - WebDriver успешно закрыт.
2025-08-23 16:36:24,893 - src.infrastructure.core.session_engine - INFO - WebDriver успешно инициализирован.
2025-08-23 16:36:35,074 - src.infrastructure.core.session_engine - INFO - Успешно загружена страница: https://www.ozon.ru/product/dzhinsy-befree-883110146/
2025-08-23 16:36:36,448 - src.infrastructure.core.session_engine - INFO - WebDriver успешно закрыт.
2025-08-23 19:27:44,984 - __main__ - INFO - Запуск Telegram-бота
2025-08-23 19:34:53,238 - TeleBot - ERROR - Infinity polling: polling exited
2025-08-23 19:34:53,239 - TeleBot - ERROR - Break infinity polling
2025-08-23 19:35:33,829 - __main__ - INFO - Запуск Telegram-бота
2025-08-23 21:12:32,611 - TeleBot - ERROR - Infinity polling exception: HTTPSConnectionPool(host='api.telegram.org', port=443): Read timed out. (read timeout=25)
2025-08-23 21:12:32,633 - TeleBot - ERROR - Exception traceback:
Traceback (most recent call last):
  File "C:\Users\edino\OneDrive\Documents\projects\pricely\.venv\Lib\site-packages\urllib3\connectionpool.py", line 534, in _make_request
    response = conn.getresponse()
  File "C:\Users\edino\OneDrive\Documents\projects\pricely\.venv\Lib\site-packages\urllib3\connection.py", line 565, in getresponse
    httplib_response = super().getresponse()
  File "C:\Users\edino\AppData\Roaming\uv\python\cpython-3.13.3-windows-x86_64-none\Lib\http\client.py", line 1430, in getresponse
    response.begin()
    ~~~~~~~~~~~~~~^^
  File "C:\Users\edino\AppData\Roaming\uv\python\cpython-3.13.3-windows-x86_64-none\Lib\http\client.py", line 331, in begin
    version, status, reason = self._read_status()
                              ~~~~~~~~~~~~~~~~~^^
  File "C:\Users\edino\AppData\Roaming\uv\python\cpython-3.13.3-windows-x86_64-none\Lib\http\client.py", line 292, in _read_status
    line = str(self.fp.readline(_MAXLINE + 1), "iso-8859-1")
               ~~~~~~~~~~~~~~~~^^^^^^^^^^^^^^
  File "C:\Users\edino\AppData\Roaming\uv\python\cpython-3.13.3-windows-x86_64-none\Lib\socket.py", line 719, in readinto
    return self._sock.recv_into(b)
           ~~~~~~~~~~~~~~~~~~~~^^^
  File "C:\Users\edino\AppData\Roaming\uv\python\cpython-3.13.3-windows-x86_64-none\Lib\ssl.py", line 1304, in recv_into
    return self.read(nbytes, buffer)
           ~~~~~~~~~^^^^^^^^^^^^^^^^
  File "C:\Users\edino\AppData\Roaming\uv\python\cpython-3.13.3-windows-x86_64-none\Lib\ssl.py", line 1138, in read
    return self._sslobj.read(len, buffer)
           ~~~~~~~~~~~~~~~~~^^^^^^^^^^^^^
TimeoutError: The read operation timed out

The above exception was the direct cause of the following exception:

Traceback (most recent call last):
  File "C:\Users\edino\OneDrive\Documents\projects\pricely\.venv\Lib\site-packages\requests\adapters.py", line 644, in send
    resp = conn.urlopen(
        method=request.method,
    ...<9 lines>...
        chunked=chunked,
    )
  File "C:\Users\edino\OneDrive\Documents\projects\pricely\.venv\Lib\site-packages\urllib3\connectionpool.py", line 841, in urlopen
    retries = retries.increment(
        method, url, error=new_e, _pool=self, _stacktrace=sys.exc_info()[2]
    )
  File "C:\Users\edino\OneDrive\Documents\projects\pricely\.venv\Lib\site-packages\urllib3\util\retry.py", line 474, in increment
    raise reraise(type(error), error, _stacktrace)
          ~~~~~~~^^^^^^^^^^^^^^^^^^^^^^^^^^^^^^^^^
  File "C:\Users\edino\OneDrive\Documents\projects\pricely\.venv\Lib\site-packages\urllib3\util\util.py", line 39, in reraise
    raise value
  File "C:\Users\edino\OneDrive\Documents\projects\pricely\.venv\Lib\site-packages\urllib3\connectionpool.py", line 787, in urlopen
    response = self._make_request(
        conn,
    ...<10 lines>...
        **response_kw,
    )
  File "C:\Users\edino\OneDrive\Documents\projects\pricely\.venv\Lib\site-packages\urllib3\connectionpool.py", line 536, in _make_request
    self._raise_timeout(err=e, url=url, timeout_value=read_timeout)
    ~~~~~~~~~~~~~~~~~~~^^^^^^^^^^^^^^^^^^^^^^^^^^^^^^^^^^^^^^^^^^^^
  File "C:\Users\edino\OneDrive\Documents\projects\pricely\.venv\Lib\site-packages\urllib3\connectionpool.py", line 367, in _raise_timeout
    raise ReadTimeoutError(
        self, url, f"Read timed out. (read timeout={timeout_value})"
    ) from err
urllib3.exceptions.ReadTimeoutError: HTTPSConnectionPool(host='api.telegram.org', port=443): Read timed out. (read timeout=25)

During handling of the above exception, another exception occurred:

Traceback (most recent call last):
  File "C:\Users\edino\OneDrive\Documents\projects\pricely\.venv\Lib\site-packages\telebot\__init__.py", line 1110, in infinity_polling
    self.polling(non_stop=True, timeout=timeout, long_polling_timeout=long_polling_timeout,
    ~~~~~~~~~~~~^^^^^^^^^^^^^^^^^^^^^^^^^^^^^^^^^^^^^^^^^^^^^^^^^^^^^^^^^^^^^^^^^^^^^^^^^^^
                 logger_level=logger_level, allowed_updates=allowed_updates, restart_on_change=False,
                 ^^^^^^^^^^^^^^^^^^^^^^^^^^^^^^^^^^^^^^^^^^^^^^^^^^^^^^^^^^^^^^^^^^^^^^^^^^^^^^^^^^^^
                 *args, **kwargs)
                 ^^^^^^^^^^^^^^^^
  File "C:\Users\edino\OneDrive\Documents\projects\pricely\.venv\Lib\site-packages\telebot\__init__.py", line 1198, in polling
    self.__threaded_polling(non_stop=non_stop, interval=interval, timeout=timeout, long_polling_timeout=long_polling_timeout,
    ~~~~~~~~~~~~~~~~~~~~~~~^^^^^^^^^^^^^^^^^^^^^^^^^^^^^^^^^^^^^^^^^^^^^^^^^^^^^^^^^^^^^^^^^^^^^^^^^^^^^^^^^^^^^^^^^^^^^^^^^^
                            logger_level=logger_level, allowed_updates=allowed_updates)
                            ^^^^^^^^^^^^^^^^^^^^^^^^^^^^^^^^^^^^^^^^^^^^^^^^^^^^^^^^^^^
  File "C:\Users\edino\OneDrive\Documents\projects\pricely\.venv\Lib\site-packages\telebot\__init__.py", line 1273, in __threaded_polling
    raise e
  File "C:\Users\edino\OneDrive\Documents\projects\pricely\.venv\Lib\site-packages\telebot\__init__.py", line 1234, in __threaded_polling
    polling_thread.raise_exceptions()
    ~~~~~~~~~~~~~~~~~~~~~~~~~~~~~~~^^
  File "C:\Users\edino\OneDrive\Documents\projects\pricely\.venv\Lib\site-packages\telebot\util.py", line 112, in raise_exceptions
    raise self.exception_info
  File "C:\Users\edino\OneDrive\Documents\projects\pricely\.venv\Lib\site-packages\telebot\util.py", line 94, in run
    task(*args, **kwargs)
    ~~~~^^^^^^^^^^^^^^^^^
  File "C:\Users\edino\OneDrive\Documents\projects\pricely\.venv\Lib\site-packages\telebot\__init__.py", line 688, in __retrieve_updates
    updates = self.get_updates(offset=(self.last_update_id + 1),
                               allowed_updates=allowed_updates,
                               timeout=timeout, long_polling_timeout=long_polling_timeout)
  File "C:\Users\edino\OneDrive\Documents\projects\pricely\.venv\Lib\site-packages\telebot\__init__.py", line 660, in get_updates
    json_updates = apihelper.get_updates(
        self.token, offset=offset, limit=limit, timeout=timeout, allowed_updates=allowed_updates,
        long_polling_timeout=long_polling_timeout)
  File "C:\Users\edino\OneDrive\Documents\projects\pricely\.venv\Lib\site-packages\telebot\apihelper.py", line 332, in get_updates
    return _make_request(token, method_url, params=payload)
  File "C:\Users\edino\OneDrive\Documents\projects\pricely\.venv\Lib\site-packages\telebot\apihelper.py", line 162, in _make_request
    result = _get_req_session().request(
        method, request_url, params=params, files=files,
        timeout=(connect_timeout, read_timeout), proxies=proxy)
  File "C:\Users\edino\OneDrive\Documents\projects\pricely\.venv\Lib\site-packages\requests\sessions.py", line 589, in request
    resp = self.send(prep, **send_kwargs)
  File "C:\Users\edino\OneDrive\Documents\projects\pricely\.venv\Lib\site-packages\requests\sessions.py", line 703, in send
    r = adapter.send(request, **kwargs)
  File "C:\Users\edino\OneDrive\Documents\projects\pricely\.venv\Lib\site-packages\requests\adapters.py", line 690, in send
    raise ReadTimeout(e, request=request)
requests.exceptions.ReadTimeout: HTTPSConnectionPool(host='api.telegram.org', port=443): Read timed out. (read timeout=25)

2025-08-23 21:19:19,185 - TeleBot - ERROR - Infinity polling exception: HTTPSConnectionPool(host='api.telegram.org', port=443): Read timed out. (read timeout=25)
2025-08-23 21:19:19,190 - TeleBot - ERROR - Exception traceback:
Traceback (most recent call last):
  File "C:\Users\edino\OneDrive\Documents\projects\pricely\.venv\Lib\site-packages\urllib3\connectionpool.py", line 534, in _make_request
    response = conn.getresponse()
  File "C:\Users\edino\OneDrive\Documents\projects\pricely\.venv\Lib\site-packages\urllib3\connection.py", line 565, in getresponse
    httplib_response = super().getresponse()
  File "C:\Users\edino\AppData\Roaming\uv\python\cpython-3.13.3-windows-x86_64-none\Lib\http\client.py", line 1430, in getresponse
    response.begin()
    ~~~~~~~~~~~~~~^^
  File "C:\Users\edino\AppData\Roaming\uv\python\cpython-3.13.3-windows-x86_64-none\Lib\http\client.py", line 331, in begin
    version, status, reason = self._read_status()
                              ~~~~~~~~~~~~~~~~~^^
  File "C:\Users\edino\AppData\Roaming\uv\python\cpython-3.13.3-windows-x86_64-none\Lib\http\client.py", line 292, in _read_status
    line = str(self.fp.readline(_MAXLINE + 1), "iso-8859-1")
               ~~~~~~~~~~~~~~~~^^^^^^^^^^^^^^
  File "C:\Users\edino\AppData\Roaming\uv\python\cpython-3.13.3-windows-x86_64-none\Lib\socket.py", line 719, in readinto
    return self._sock.recv_into(b)
           ~~~~~~~~~~~~~~~~~~~~^^^
  File "C:\Users\edino\AppData\Roaming\uv\python\cpython-3.13.3-windows-x86_64-none\Lib\ssl.py", line 1304, in recv_into
    return self.read(nbytes, buffer)
           ~~~~~~~~~^^^^^^^^^^^^^^^^
  File "C:\Users\edino\AppData\Roaming\uv\python\cpython-3.13.3-windows-x86_64-none\Lib\ssl.py", line 1138, in read
    return self._sslobj.read(len, buffer)
           ~~~~~~~~~~~~~~~~~^^^^^^^^^^^^^
TimeoutError: The read operation timed out

The above exception was the direct cause of the following exception:

Traceback (most recent call last):
  File "C:\Users\edino\OneDrive\Documents\projects\pricely\.venv\Lib\site-packages\requests\adapters.py", line 644, in send
    resp = conn.urlopen(
        method=request.method,
    ...<9 lines>...
        chunked=chunked,
    )
  File "C:\Users\edino\OneDrive\Documents\projects\pricely\.venv\Lib\site-packages\urllib3\connectionpool.py", line 841, in urlopen
    retries = retries.increment(
        method, url, error=new_e, _pool=self, _stacktrace=sys.exc_info()[2]
    )
  File "C:\Users\edino\OneDrive\Documents\projects\pricely\.venv\Lib\site-packages\urllib3\util\retry.py", line 474, in increment
    raise reraise(type(error), error, _stacktrace)
          ~~~~~~~^^^^^^^^^^^^^^^^^^^^^^^^^^^^^^^^^
  File "C:\Users\edino\OneDrive\Documents\projects\pricely\.venv\Lib\site-packages\urllib3\util\util.py", line 39, in reraise
    raise value
  File "C:\Users\edino\OneDrive\Documents\projects\pricely\.venv\Lib\site-packages\urllib3\connectionpool.py", line 787, in urlopen
    response = self._make_request(
        conn,
    ...<10 lines>...
        **response_kw,
    )
  File "C:\Users\edino\OneDrive\Documents\projects\pricely\.venv\Lib\site-packages\urllib3\connectionpool.py", line 536, in _make_request
    self._raise_timeout(err=e, url=url, timeout_value=read_timeout)
    ~~~~~~~~~~~~~~~~~~~^^^^^^^^^^^^^^^^^^^^^^^^^^^^^^^^^^^^^^^^^^^^
  File "C:\Users\edino\OneDrive\Documents\projects\pricely\.venv\Lib\site-packages\urllib3\connectionpool.py", line 367, in _raise_timeout
    raise ReadTimeoutError(
        self, url, f"Read timed out. (read timeout={timeout_value})"
    ) from err
urllib3.exceptions.ReadTimeoutError: HTTPSConnectionPool(host='api.telegram.org', port=443): Read timed out. (read timeout=25)

During handling of the above exception, another exception occurred:

Traceback (most recent call last):
  File "C:\Users\edino\OneDrive\Documents\projects\pricely\.venv\Lib\site-packages\telebot\__init__.py", line 1110, in infinity_polling
    self.polling(non_stop=True, timeout=timeout, long_polling_timeout=long_polling_timeout,
    ~~~~~~~~~~~~^^^^^^^^^^^^^^^^^^^^^^^^^^^^^^^^^^^^^^^^^^^^^^^^^^^^^^^^^^^^^^^^^^^^^^^^^^^
                 logger_level=logger_level, allowed_updates=allowed_updates, restart_on_change=False,
                 ^^^^^^^^^^^^^^^^^^^^^^^^^^^^^^^^^^^^^^^^^^^^^^^^^^^^^^^^^^^^^^^^^^^^^^^^^^^^^^^^^^^^
                 *args, **kwargs)
                 ^^^^^^^^^^^^^^^^
  File "C:\Users\edino\OneDrive\Documents\projects\pricely\.venv\Lib\site-packages\telebot\__init__.py", line 1198, in polling
    self.__threaded_polling(non_stop=non_stop, interval=interval, timeout=timeout, long_polling_timeout=long_polling_timeout,
    ~~~~~~~~~~~~~~~~~~~~~~~^^^^^^^^^^^^^^^^^^^^^^^^^^^^^^^^^^^^^^^^^^^^^^^^^^^^^^^^^^^^^^^^^^^^^^^^^^^^^^^^^^^^^^^^^^^^^^^^^^
                            logger_level=logger_level, allowed_updates=allowed_updates)
                            ^^^^^^^^^^^^^^^^^^^^^^^^^^^^^^^^^^^^^^^^^^^^^^^^^^^^^^^^^^^
  File "C:\Users\edino\OneDrive\Documents\projects\pricely\.venv\Lib\site-packages\telebot\__init__.py", line 1273, in __threaded_polling
    raise e
  File "C:\Users\edino\OneDrive\Documents\projects\pricely\.venv\Lib\site-packages\telebot\__init__.py", line 1234, in __threaded_polling
    polling_thread.raise_exceptions()
    ~~~~~~~~~~~~~~~~~~~~~~~~~~~~~~~^^
  File "C:\Users\edino\OneDrive\Documents\projects\pricely\.venv\Lib\site-packages\telebot\util.py", line 112, in raise_exceptions
    raise self.exception_info
  File "C:\Users\edino\OneDrive\Documents\projects\pricely\.venv\Lib\site-packages\telebot\util.py", line 94, in run
    task(*args, **kwargs)
    ~~~~^^^^^^^^^^^^^^^^^
  File "C:\Users\edino\OneDrive\Documents\projects\pricely\.venv\Lib\site-packages\telebot\__init__.py", line 688, in __retrieve_updates
    updates = self.get_updates(offset=(self.last_update_id + 1),
                               allowed_updates=allowed_updates,
                               timeout=timeout, long_polling_timeout=long_polling_timeout)
  File "C:\Users\edino\OneDrive\Documents\projects\pricely\.venv\Lib\site-packages\telebot\__init__.py", line 660, in get_updates
    json_updates = apihelper.get_updates(
        self.token, offset=offset, limit=limit, timeout=timeout, allowed_updates=allowed_updates,
        long_polling_timeout=long_polling_timeout)
  File "C:\Users\edino\OneDrive\Documents\projects\pricely\.venv\Lib\site-packages\telebot\apihelper.py", line 332, in get_updates
    return _make_request(token, method_url, params=payload)
  File "C:\Users\edino\OneDrive\Documents\projects\pricely\.venv\Lib\site-packages\telebot\apihelper.py", line 162, in _make_request
    result = _get_req_session().request(
        method, request_url, params=params, files=files,
        timeout=(connect_timeout, read_timeout), proxies=proxy)
  File "C:\Users\edino\OneDrive\Documents\projects\pricely\.venv\Lib\site-packages\requests\sessions.py", line 589, in request
    resp = self.send(prep, **send_kwargs)
  File "C:\Users\edino\OneDrive\Documents\projects\pricely\.venv\Lib\site-packages\requests\sessions.py", line 703, in send
    r = adapter.send(request, **kwargs)
  File "C:\Users\edino\OneDrive\Documents\projects\pricely\.venv\Lib\site-packages\requests\adapters.py", line 690, in send
    raise ReadTimeout(e, request=request)
requests.exceptions.ReadTimeout: HTTPSConnectionPool(host='api.telegram.org', port=443): Read timed out. (read timeout=25)

